# Error and Exception Handling in Python

No matter how good a programmer you are, errors are inevitable. Exception handling is the process of responding to and managing errors that arise during the execution of a program. In Python, this is done using `try...except` blocks.

---

## 1. What is an Exception?

An exception is an event, which occurs during the execution of a program, that disrupts the normal flow of the program's instructions. When a Python script raises an exception, it must either be handled immediately or it will terminate the program.

Consider this code:
```python
numerator = 10
denominator = 0

result = numerator / denominator  # This will raise a ZeroDivisionError
print(result)

print("This line will never be executed.")
```
The program crashes when it tries to divide by zero.

---

## 2. The `try...except` Block

To handle such errors gracefully, you can use a `try...except` block.

-   The **`try`** block lets you test a block of code for errors.
-   The **`except`** block lets you handle the error.

```python
numerator = 10
denominator = 0

try:
    # Code that might cause an error
    result = numerator / denominator
    print(result)
except ZeroDivisionError:
    # Code to run if a ZeroDivisionError occurs
    print("Error: You cannot divide by zero!")

print("This line will now be executed because the error was handled.")
```

### Handling Multiple Exceptions

You can handle multiple types of exceptions by adding more `except` blocks.

```python
try:
    my_list = [1, 2, 3]
    value = my_list[5]  # This will raise an IndexError
    result = 10 / 0     # This line won't be reached
except ZeroDivisionError:
    print("Error: Cannot divide by zero.")
except IndexError:
    print("Error: Index is out of range.")
```

You can also handle multiple exceptions in a single `except` block by passing them as a tuple.

```python
try:
    # Some code that could raise one of several errors
    ...
except (ZeroDivisionError, IndexError) as e:
    print(f"An error occurred: {e}")
```

### Catching the Exception Object

You can catch the exception object itself to get more details about the error. This is done using `as e` (where `e` is a variable name).

```python
try:
    result = 'a' + 10
except TypeError as e:
    print(f"A TypeError occurred: {e}")
```
**Output:**
```
A TypeError occurred: can only concatenate str (not "int") to str
```

### The Generic `except` Block

You can use a bare `except:` block to catch any and all exceptions. However, this is generally **not recommended** because it can hide unexpected errors and make debugging difficult. It's always better to specify the exact exceptions you intend to catch.

```python
try:
    # Some code
    ...
except: # Catches all exceptions
    print("An unknown error occurred.")
```

---

## 3. The `else` and `finally` Clauses

The `try...except` block has two optional clauses: `else` and `finally`.

### The `else` Clause

The `else` block is executed **only if no exceptions were raised** in the `try` block. It's useful for code that should run only when the `try` block was successful.

```python
try:
    numerator = 10
    denominator = 2
    result = numerator / denominator
except ZeroDivisionError:
    print("Cannot divide by zero.")
else:
    # This will run because no error occurred
    print(f"The result is {result}")
```

### The `finally` Clause

The `finally` block is executed **no matter what**. It runs whether an exception was raised or not. This is extremely useful for cleanup operations, such as closing a file or a network connection.

```python
file = None
try:
    file = open("some_file.txt", "r")
    # Do something with the file
    print("File opened successfully.")
except FileNotFoundError:
    print("Error: File not found.")
finally:
    # This block always runs
    if file:
        file.close()
        print("File closed.")
```

---

## 4. Raising an Exception

You can raise an exception yourself using the `raise` keyword. This is useful when you want to enforce certain conditions in your code.

```python
def set_age(age):
    if age < 0:
        # Raise a ValueError if the age is invalid
        raise ValueError("Age cannot be negative.")
    print(f"Age is set to {age}")

try:
    set_age(-5)
except ValueError as e:
    print(f"Error: {e}")
```
This allows you to create more robust and predictable functions that signal clearly when they are being used incorrectly.
